Traceback (most recent call last):
  File "/Users/veramazeeva/Library/CloudStorage/OneDrive-Personal/Carnegie Mellon/GenAI/project/code/main.py", line 109, in <module>
    trainer.run()
  File "/Users/veramazeeva/Library/CloudStorage/OneDrive-Personal/Carnegie Mellon/GenAI/project/code/src/train/train.py", line 80, in run
    loss, logits, *_ = self.model(**encodings)
                      ^^^^^^^^^^^^^^^^^^^^^^^
  File "/opt/anaconda3/lib/python3.12/site-packages/torch/nn/modules/module.py", line 1553, in _wrapped_call_impl
    return self._call_impl(*args, **kwargs)
           ^^^^^^^^^^^^^^^^^^^^^^^^^^^^^^^^
  File "/opt/anaconda3/lib/python3.12/site-packages/torch/nn/modules/module.py", line 1562, in _call_impl
    return forward_call(*args, **kwargs)
           ^^^^^^^^^^^^^^^^^^^^^^^^^^^^^
  File "/Users/veramazeeva/Library/CloudStorage/OneDrive-Personal/Carnegie Mellon/GenAI/project/code/src/models/gpt.py", line 202, in forward
    x = block(x, mask=mask)
        ^^^^^^^^^^^^^^^^^^^
  File "/opt/anaconda3/lib/python3.12/site-packages/torch/nn/modules/module.py", line 1553, in _wrapped_call_impl
    return self._call_impl(*args, **kwargs)
           ^^^^^^^^^^^^^^^^^^^^^^^^^^^^^^^^
  File "/opt/anaconda3/lib/python3.12/site-packages/torch/nn/modules/module.py", line 1562, in _call_impl
    return forward_call(*args, **kwargs)
           ^^^^^^^^^^^^^^^^^^^^^^^^^^^^^
TypeError: Block.forward() got an unexpected keyword argument 'mask'
